Workbook

Sheet Cover & Sign-off
A1: RevRecon: Revenue Leakage & SLA Billing Reconciliation
A2: Period under review: Oct 2025 to Sep 2026
A4: Objective
A5: Confirm every contract-period with metered usage was invoiced at the contracted tier price, net of any SLA credit owed (BRD BR-01 to BR-05).
A7: Procedures
A8: 1. Re-perform expected billing from usage events and contract terms (Recon Detail).
A9: 2. Agree each expected amount to the invoice register; investigate differences over 0.01.
A10: 3. Classify each exception by root cause and assign an owner (Exceptions).
A11: 4. Agree Summary totals to vw_billing_reconciliation in MySQL and to the Power BI Executive Summary.
A13: Tickmark legend
A14: R Re-performed: recalculated from source data without exception
A15: A Agreed to invoice register
... A23: Date reviewed

Sheet Summary
A1: Exception Type | B1: Count | C1: Net Leakage | D1: Under-billed | E1: Over-billed
A2: UNBILLED_USAGE | B2: =COUNTIFS('Recon Detail'!$R$2:$R$692,A2) | C2: =SUMIFS('Recon Detail'!$Q$2:$Q$692,'Recon Detail'!$R$2:$R$692,A2) | D2: =SUMIFS('Recon Detail'!$Q$2:$Q$692,'Recon Detail'!$R$2:$R$692,A2,'Recon Detail'!$Q$2:$Q$692,">0") | E2: =-SUMIFS('Recon Detail'!$Q$2:$Q$692,'Recon Detail'!$R$2:$R$692,A2,'Recon Detail'!$Q$2:$Q$692,"<0")
A3: TIER_PRICING_VARIANCE | B3: =COUNTIFS('Recon Detail'!$R$2:$R$692,A3) | C3: =SUMIFS('Recon Detail'!$Q$2:$Q$692,'Recon Detail'!$R$2:$R$692,A3) | D3: =SUMIFS('Recon Detail'!$Q$2:$Q$692,'Recon Detail'!$R$2:$R$692,A3,'Recon Detail'!$Q$2:$Q$692,">0") | E3: =-SUMIFS('Recon Detail'!$Q$2:$Q$692,'Recon Detail'!$R$2:$R$692,A3,'Recon Detail'!$Q$2:$Q$692,"<0")
A4: MISSED_SLA_CREDIT | B4: =COUNTIFS('Recon Detail'!$R$2:$R$692,A4) | C4: =SUMIFS('Recon Detail'!$Q$2:$Q$692,'Recon Detail'!$R$2:$R$692,A4) | D4: =SUMIFS('Recon Detail'!$Q$2:$Q$692,'Recon Detail'!$R$2:$R$692,A4,'Recon Detail'!$Q$2:$Q$692,">0") | E4: =-SUMIFS('Recon Detail'!$Q$2:$Q$692,'Recon Detail'!$R$2:$R$692,A4,'Recon Detail'!$Q$2:$Q$692,"<0")
A5: RECONCILED | B5: =COUNTIFS('Recon Detail'!$R$2:$R$692,A5) | C5: =SUMIFS('Recon Detail'!$Q$2:$Q$692,'Recon Detail'!$R$2:$R$692,A5) | D5: =SUMIFS('Recon Detail'!$Q$2:$Q$692,'Recon Detail'!$R$2:$R$692,A5,'Recon Detail'!$Q$2:$Q$692,">0") | E5: =-SUMIFS('Recon Detail'!$Q$2:$Q$692,'Recon Detail'!$R$2:$R$692,A5,'Recon Detail'!$Q$2:$Q$692,"<0")
A6: Total | B6: =SUM(B2:B5) | C6: =SUM(C2:C5) | D6: =SUM(D2:D5) | E6: =SUM(E2:E5)
A11: Total Expected Revenue | B11: =SUM('Recon Detail'!$N$2:$N$692)
A12: Total Billed Revenue | B12: =SUM('Recon Detail'!$P$2:$P$692)
A13: Net Leakage Variance | B13: =B11-B12
A14: % Leakage Exposure | B14: =IF(B11=0,0,B13/B11)
A15: Gross Exposure (under + over) | B15: =D6+E6

Sheet Recon Detail
A1: Customer ID | B1: Company | C1: Tier | D1: Contract ID | E1: Billing Period | F1: Events | G1: Units | H1: Billable Units | I1: Availability % | J1: SLA Target % | K1: Credit % | L1: Gross Expected | M1: SLA Credit | N1: Net Expected | O1: Invoice ID | P1: Billed | Q1: Leakage | R1: Exception Type | S1: Tickmark
A2: 1 | B2: Rodriguez, Figueroa and Sanchez | C2: Starter | D2: 5001 | E2: 45931 | F2: 49 | G2: 1871 | H2: 1871 | I2: 100 | J2: 98 | K2: 0 | L2: 314.52 | M2: 0 | N2: 314.52 | O2: 100001 | P2: 314.52 | Q2: 0 | R2: RECONCILED
A3: 2 | B3: Doyle Ltd | C3: Starter | D3: 5002 | E3: 45931 | F3: 30 | G3: 956 | H3: 1100 | I3: 100 | J3: 98 | K3: 0 | L3: 188.21 | M3: 0 | N3: 188.21 | O3: 100002 | P3: 188.21 | Q3: 0 | R3: RECONCILED
A4: 3 | B4: Mcclain, Miller and Henderson | C4: Growth | D4: 5003 | E4: 45931 | F4: 38 | G4: 1079 | H4: 1400 | I4: 100 | J4: 99 | K4: 0 | L4: 151.58 | M4: 0 | N4: 151.58 | O4: 100003 | P4: 151.58 | Q4: 0 | R4: RECONCILED
A5: 5 | B5: Guzman, Hoffman and Baldwin | C5: Enterprise | D5: 5005 | E5: 45931 | F5: 178 | G5: 5763 | H5: 5763 | I5: 98.876 | J5: 99.5 | K5: 0.1 | L5: 341.63 | M5: 34.16 | N5: 307.47 | O5: 100004 | P5: 307.47 | Q5: 0 | R5: RECONCILED
A6: 6 | B6: Gardner, Robinson and Lawrence | C6: Enterprise | D6: 5006 | E6: 45931 | F6: 88 | G6: 2828 | H6: 2828 | I6: 100 | J6: 99.5 | K6: 0 | L6: 192.3 | M6: 0 | N6: 192.3 | O6: 100005 | P6: 192.3 | Q6: 0 | R6: RECONCILED
A7: 7 | B7: Blake and Sons | C7: Starter | D7: 5007 | E7: 45931 | F7: 65 | G7: 1928 | H7: 1928 | I7: 90.769 | J7: 98 | K7: 0.25 | L7: 316.38 | M7: 79.1 | N7: 237.28 | O7: 100006 | P7: 316.38 | Q7: -79.1 | R7: MISSED_SLA_CREDIT
A8: 8 | B8: Henderson, Ramirez and Lewis | C8: Enterprise | D8: 5008 | E8: 45931 | F8: 137 | G8: 4226 | H8: 4800 | I8: 100 | J8: 99.5 | K8: 0 | L8: 320.26 | M8: 0 | N8: 320.26 | O8: 100007 | P8: 320.26 | Q8: 0 | R8: RECONCILED
A9: 9 | B9: Garcia-James | C9: Growth | D9: 5009 | E9: 45931 | F9: 40 | G9: 1288 | H9: 1500 | I9: 100 | J9: 99 | K9: 0 | L9: 152.01 | M9: 0 | N9: 152.01 | O9: 100008 | P9: 152.01 | Q9: 0 | R9: RECONCILED
A10: 10 | B10: Abbott-Munoz | C10: Starter | D10: 5010 | E10: 45931 | F10: 38 | G10: 1217 | H10: 1217 | I10: 100 | J10: 98 | K10: 0 | L10: 184.74 | M10: 0 | N10: 184.74 | O10: 100009 | P10: 184.74 | Q10: 0 | R10: RECONCILED
A11: 11 | B11: Blair PLC | C11: Enterprise | D11: 5011 | E11: 45931 | F11: 84 | G11: 2625 | H11: 2700 | I11: 100 | J11: 99.5 | K11: 0 | L11: 148.61 | M11: 0 | N11: 148.61 | O11: 100010 | P11: 148.61 | Q11: 0 | R11: RECONCILED
A12: 12 | B12: Dudley Group | C12: Starter | D12: 5012 | E12: 45931 | F12: 44 | G12: 1557 | H12: 1557 | I12: 100 | J12: 98 | K12: 0 | L12: 215.33 | M12: 0 | N12: 215.33 | O12: 100011 | P12: 215.33 | Q12: 0 | R12: RECONCILED
A13: 13 | B13: Arnold Ltd | C13: Enterprise | D13: 5013 | E13: 45931 | F13: 111 | G13: 3814 | H13: 3814 | I13: 100 | J13: 99.5 | K13: 0 | L13: 197.11 | M13: 0 | N13: 197.11 | O13: 100012 | P13: 197.11 | Q13: 0 | R13: RECONCILED
... A23: 24 | B23: Morales-Jones | C23: Starter | D23: 5024 | E23: 45931 | F23: 41 | G23: 1380 | H23: 1400 | I23: 100 | J23: 98 | K23: 0 | L23: 238.56 | M23: 0 | N23: 238.56 | O23: 100022 | P23: 238.56 | Q23: 0 | R23: RECONCILED
A24: 26 | B24: Wilkerson-Day | C24: Enterprise | D24: 5026 | E24: 45931 | F24: 151 | G24: 4921 | H24: 5400 | I24: 97.351 | J24: 99.5 | K24: 0.25 | L24: 374.98 | M24: 93.75 | N24: 281.23 | Q24: 281.23 | R24: UNBILLED_USAGE
A25: 27 | B25: Baker and Sons | C25: Growth | D25: 5027 | E25: 45931 | F25: 89 | G25: 2656 | H25: 2656 | I25: 100 | J25: 99 | K25: 0 | L25: 286.61 | M25: 0 | N25: 286.61 | O25: 100023 | P25: 254.76 | Q25: 31.85 | R25: TIER_PRICING_VARIANCE
A26: 29 | B26: Ross, Robinson and Bright | C26: Growth | D26: 5029 | E26: 45931 | F26: 55 | G26: 1751 | H26: 2100 | I26: 100 | J26: 99 | K26: 0 | L26: 207.9 | M26: 0 | N26: 207.9 | O26: 100024 | P26: 207.9 | Q26: 0 | R26: RECONCILED
A27: 30 | B27: Snyder, Campos and Callahan | C27: Enterprise | D27: 5030 | E27: 45931 | F27: 95 | G27: 3102 | H27: 3102 | I27: 100 | J27: 99.5 | K27: 0 | L27: 186.62 | M27: 0 | N27: 186.62 | O27: 100025 | P27: 186.62 | Q27: 0 | R27: RECONCILED
A28: 31 | B28: Burton Ltd | C28: Starter | D28: 5031 | E28: 45931 | F28: 66 | G28: 2181 | H28: 2181 | I28: 100 | J28: 98 | K28: 0 | L28: 297.92 | M28: 0 | N28: 297.92 | O28: 100026 | P28: 297.92 | Q28: 0 | R28: RECONCILED
A29: 32 | B29: Carlson-Cruz | C29: Enterprise | D29: 5032 | E29: 45931 | F29: 110 | G29: 3456 | H29: 3456 | I29: 100 | J29: 99.5 | K29: 0 | L29: 245.24 | M29: 0 | N29: 245.24 | O29: 100027 | P29: 245.24 | Q29: 0 | R29: RECONCILED
A30: 34 | B30: Frazier Inc | C30: Growth | D30: 5034 | E30: 45931 | F30: 102 | G30: 3534 | H30: 3534 | I30: 100 | J30: 99 | K30: 0 | L30: 386.12 | M30: 0 | N30: 386.12 | O30: 100028 | P30: 386.12 | Q30: 0 | R30: RECONCILED
A31: 35 | B31: Dyer, Potter and Mack | C31: Enterprise | D31: 5035 | E31: 45931 | F31: 159 | G31: 5405 | H31: 5405 | I31: 100 | J31: 99.5 | K31: 0 | L31: 338.14 | M31: 0 | N31: 338.14 | O31: 100029 | P31: 338.14 | Q31: 0 | R31: RECONCILED
A32: 36 | B32: Rodriguez-Graham | C32: Starter | D32: 5036 | E32: 45931 | F32: 42 | G32: 1318 | H32: 1318 | I32: 100 | J32: 98 | K32: 0 | L32: 228.54 | M32: 0 | N32: 228.54 | Q32: 228.54 | R32: UNBILLED_USAGE
A33: 37 | B33: Smith-Bowen | C33: Growth | D33: 5037 | E33: 45931 | F33: 82 | G33: 2489 | H33: 2489 | I33: 100 | J33: 99 | K33: 0 | L33: 207.66 | M33: 0 | N33: 207.66 | O33: 100030 | P33: 184.58 | Q33: 23.08 | R33: TIER_PRICING_VARIANCE
A34: 38 | B34: Baker, Mason and White | C34: Growth | D34: 5038 | E34: 45931 | F34: 55 | G34: 1719 | H34: 2000 | I34: 100 | J34: 99 | K34: 0 | L34: 173.88 | M34: 0 | N34: 173.88 | O34: 100031 | P34: 173.88 | Q34: 0 | R34: RECONCILED
A35: 39 | B35: Harrell LLC | C35: Enterprise | D35: 5039 | E35: 45931 | F35: 71 | G35: 2371 | H35: 2371 | I35: 100 | J35: 99.5 | K35: 0 | L35: 116.84 | M35: 0 | N35: 116.84 | O35: 100032 | P35: 116.84 | Q35: 0 | R35: RECONCILED
A36: 40 | B36: Romero, Gonzalez and Brooks | C36: Growth | D36: 5040 | E36: 45931 | F36: 64 | G36: 2089 | H36: 2089 | I36: 100 | J36: 99 | K36: 0 | L36: 233.13 | M36: 0 | N36: 233.13 | O36: 100033 | P36: 233.13 | Q36: 0 | R36: RECONCILED
A37: 41 | B37: Ryan PLC | C37: Enterprise | D37: 5041 | E37: 45931 | F37: 105 | G37: 3707 | H37: 3707 | I37: 100 | J37: 99.5 | K37: 0 | L37: 182.38 | M37: 0 | N37: 182.38 | O37: 100034 | P37: 182.38 | Q37: 0 | R37: RECONCILED
A38: 42 | B38: George Group | C38: Growth | D38: 5042 | E38: 45931 | F38: 97 | G38: 3141 | H38: 3141 | I38: 100 | J38: 99 | K38: 0 | L38: 265.73 | M38: 0 | N38: 265.73 | O38: 100035 | P38: 265.73 | Q38: 0 | R38: RECONCILED
A39: 44 | B39: Allen-Allen | C39: Enterprise | D39: 5044 | E39: 45931 | F39: 159 | G39: 5436 | H39: 5436 | I39: 100 | J39: 99.5 | K39: 0 | L39: 344.42 | M39: 0 | N39: 344.42 | O39: 100036 | P39: 344.42 | Q39: 0 | R39: RECONCILED
A40: 45 | B40: Arroyo, Miller and Tucker | C40: Enterprise | D40: 5045 | E40: 45931 | F40: 129 | G40: 4059 | H40: 4059 | I40: 100 | J40: 99.5 | K40: 0 | L40: 230.55 | M40: 0 | N40: 230.55 | O40: 100037 | P40: 230.55 | Q40: 0 | R40: RECONCILED
A41: 46 | B41: Spence PLC | C41: Growth | D41: 5046 | E41: 45931 | F41: 64 | G41: 2063 | H41: 2063 | I41: 100 | J41: 99 | K41: 0 | L41: 202.75 | M41: 0 | N41: 202.75 | O41: 100038 | P41: 202.75 | Q41: 0 | R41: RECONCILED
A42: 47 | B42: Anderson Group | C42: Growth | D42: 5047 | E42: 45931 | F42: 78 | G42: 2533 | H42: 2533 | I42: 100 | J42: 99 | K42: 0 | L42: 262.85 | M42: 0 | N42: 262.85 | O42: 100039 | P42: 262.85 | Q42: 0 | R42: RECONCILED
A43: 48 | B43: Martin, Rose and Obrien | C43: Enterprise | D43: 5048 | E43: 45931 | F43: 134 | G43: 4303 | H43: 4303 | I43: 100 | J43: 99.5 | K43: 0 | L43: 269.88 | M43: 0 | N43: 269.88 | O43: 100040 | P43: 269.88 | Q43: 0 | R43: RECONCILED
A44: 51 | B44: Brooks, Lam and Hayes | C44: Growth | D44: 5051 | E44: 45931 | F44: 67 | G44: 2275 | H44: 2300 | I44: 100 | J44: 99 | K44: 0 | L44: 249.64 | M44: 0 | N44: 249.64 | O44: 100041 | P44: 249.64 | Q44: 0 | R44: RECONCILED
... A64: 14 | B64: Mcclure, Ward and Lee | C64: Starter | D64: 5014 | E64: 45962 | F64: 37 | G64: 1236 | H64: 1236 | I64: 100 | J64: 98 | K64: 0 | L64: 166.12 | M64: 0 | N64: 166.12 | O64: 100061 | P64: 166.12 | Q64: 0 | R64: RECONCILED
A65: 16 | B65: Galloway-Wyatt | C65: Starter | D65: 5016 | E65: 45962 | F65: 21 | G65: 620 | H65: 800 | I65: 100 | J65: 98 | K65: 0 | L65: 112.08 | M65: 0 | N65: 112.08 | Q65: 112.08 | R65: UNBILLED_USAGE
A66: 17 | B66: James Group | C66: Growth | D66: 5017 | E66: 45962 | F66: 103 | G66: 2915 | H66: 2915 | I66: 93.204 | J66: 99 | K66: 0.25 | L66: 281.5 | M66: 70.38 | N66: 211.12 | O66: 100062 | P66: 211.12 | Q66: 0 | R66: RECONCILED
A67: 18 | B67: Flowers, Martin and Kelly | C67: Growth | D67: 5018 | E67: 45962 | F67: 45 | G67: 1376 | H67: 1376 | I67: 100 | J67: 99 | K67: 0 | L67: 135.98 | M67: 0 | N67: 135.98 | O67: 100063 | P67: 135.98 | Q67: 0 | R67: RECONCILED
A68: 19 | B68: Adams, Zuniga and Wong | C68: Growth | D68: 5019 | E68: 45962 | F68: 79 | G68: 2727 | H68: 2727 | I68: 100 | J68: 99 | K68: 0 | L68: 277.83 | M68: 0 | N68: 277.83 | O68: 100064 | P68: 277.83 | Q68: 0 | R68: RECONCILED
...

Sheet Exceptions
A1: Customer ID | B1: Company | C1: Tier | D1: Contract ID | E1: Billing Period | F1: Events | G1: Units | H1: Billable Units | I1: Availability % | J1: SLA Target % | K1: Credit % | L1: Gross Expected | M1: SLA Credit | N1: Net Expected | O1: Invoice ID | P1: Billed | Q1: Leakage | R1: Exception Type | S1: Root Cause Confirmed | T1: Owner | U1: Resolution | V1: Status
A2: 7 | B2: Blake and Sons | C2: Starter | D2: 5007 | E2: 45931 | F2: 65 | G2: 1928 | H2: 1928 | I2: 90.769 | J2: 98 | K2: 0.25 | L2: 316.38 | M2: 79.1 | N2: 237.28 | O2: 100006 | P2: 316.38 | Q2: -79.1 | R2: MISSED_SLA_CREDIT
A3: 14 | B3: Mcclure, Ward and Lee | C3: Starter | D3: 5014 | E3: 45931 | F3: 31 | G3: 896 | H3: 1000 | I3: 93.548 | J3: 98 | K3: 0.25 | L3: 134.4 | M3: 33.6 | N3: 100.8 | O3: 100013 | P3: 134.4 | Q3: -33.6 | R3: MISSED_SLA_CREDIT
A4: 26 | B4: Wilkerson-Day | C4: Enterprise | D4: 5026 | E4: 45931 | F4: 151 | G4: 4921 | H4: 5400 | I4: 97.351 | J4: 99.5 | K4: 0.25 | L4: 374.98 | M4: 93.75 | N4: 281.23 | Q4: 281.23 | R4: UNBILLED_USAGE
A5: 27 | B5: Baker and Sons | C5: Growth | D5: 5027 | E5: 45931 | F5: 89 | G5: 2656 | H5: 2656 | I5: 100 | J5: 99 | K5: 0 | L5: 286.61 | M5: 0 | N5: 286.61 | O5: 100023 | P5: 254.76 | Q5: 31.85 | R5: TIER_PRICING_VARIANCE
A6: 36 | B6: Rodriguez-Graham | C6: Starter | D6: 5036 | E6: 45931 | F6: 42 | G6: 1318 | H6: 1318 | I6: 100 | J6: 98 | K6: 0 | L6: 228.54 | M6: 0 | N6: 228.54 | Q6: 228.54 | R6: UNBILLED_USAGE
A7: 37 | B7: Smith-Bowen | C7: Growth | D7: 5037 | E7: 45931 | F7: 82 | G7: 2489 | H7: 2489 | I7: 100 | J7: 99 | K7: 0 | L7: 207.66 | M7: 0 | N7: 207.66 | O7: 100030 | P7: 184.58 | Q7: 23.08 | R7: TIER_PRICING_VARIANCE
A8: 57 | B8: Washington, Ryan and Cummings | C8: Growth | D8: 5057 | E8: 45931 | F8: 55 | G8: 1916 | H8: 1916 | I8: 100 | J8: 99 | K8: 0 | L8: 186.75 | M8: 0 | N8: 186.75 | O8: 100045 | P8: 207.5 | Q8: -20.75 | R8: TIER_PRICING_VARIANCE
A9: 2 | B9: Doyle Ltd | C9: Starter | D9: 5002 | E9: 45962 | F9: 38 | G9: 1168 | H9: 1168 | I9: 97.368 | J9: 98 | K9: 0.1 | L9: 199.84 | M9: 19.98 | N9: 179.86 | O9: 100050 | P9: 199.84 | Q9: -19.98 | R9: MISSED_SLA_CREDIT
A10: 16 | B10: Galloway-Wyatt | C10: Starter | D10: 5016 | E10: 45962 | F10: 21 | G10: 620 | H10: 800 | I10: 100 | J10: 98 | K10: 0 | L10: 112.08 | M10: 0 | N10: 112.08 | Q10: 112.08 | R10: UNBILLED_USAGE
A11: 31 | B11: Burton Ltd | C11: Starter | D11: 5031 | E11: 45962 | F11: 48 | G11: 1699 | H11: 1699 | I11: 100 | J11: 98 | K11: 0 | L11: 232.08 | M11: 0 | N11: 232.08 | Q11: 232.08 | R11: UNBILLED_USAGE
A12: 51 | B12: Brooks, Lam and Hayes | C12: Growth | D12: 5051 | E12: 45962 | F12: 66 | G12: 2058 | H12: 2300 | I12: 96.97 | J12: 99 | K12: 0.25 | L12: 249.64 | M12: 62.41 | N12: 187.23 | O12: 100090 | P12: 249.64 | Q12: -62.41 | R12: MISSED_SLA_CREDIT
A13: 3 | B13: Mcclain, Miller and Henderson | C13: Growth | D13: 5003 | E13: 45992 | F13: 46 | G13: 1565 | H13: 1565 | I13: 100 | J13: 99 | K13: 0 | L13: 169.44 | M13: 0 | N13: 169.44 | O13: 100101 | P13: 188.27 | Q13: -18.83 | R13: TIER_PRICING_VARIANCE
A14: 27 | B14: Baker and Sons | C14: Growth | D14: 5027 | E14: 45992 | F14: 83 | G14: 2784 | H14: 2784 | I14: 100 | J14: 99 | K14: 0 | L14: 300.42 | M14: 0 | N14: 300.42 | Q14: 300.42 | R14: UNBILLED_USAGE
A15: 36 | B15: Rodriguez-Graham | C15: Starter | D15: 5036 | E15: 45992 | F15: 32 | G15: 1063 | H15: 1100 | I15: 100 | J15: 98 | K15: 0 | L15: 190.74 | M15: 0 | N15: 190.74 | Q15: 190.74 | R15: UNBILLED_USAGE
A16: 57 | B16: Washington, Ryan and Cummings | C16: Growth | D16: 5057 | E16: 45992 | F16: 50 | G16: 1573 | H16: 1900 | I16: 100 | J16: 99 | K16: 0 | L16: 185.19 | M16: 0 | N16: 185.19 | Q16: 185.19 | R16: UNBILLED_USAGE
A17: 60 | B17: Gomez-Jenkins | C17: Starter | D17: 5060 | E17: 45992 | F17: 23 | G17: 784 | H17: 800 | I17: 100 | J17: 98 | K17: 0 | L17: 140.4 | M17: 0 | N17: 140.4 | Q17: 140.4 | R17: UNBILLED_USAGE
A18: 11 | B18: Blair PLC | C18: Enterprise | D18: 5011 | E18: 46023 | F18: 90 | G18: 2885 | H18: 2885 | I18: 100 | J18: 99.5 | K18: 0 | L18: 158.79 | M18: 0 | N18: 158.79 | O18: 100160 | P18: 198.49 | Q18: -39.7 | R18: TIER_PRICING_VARIANCE
A19: 24 | B19: Morales-Jones | C19: Starter | D19: 5024 | E19: 46023 | F19: 48 | G19: 1642 | H19: 1642 | I19: 100 | J19: 98 | K19: 0 | L19: 279.8 | M19: 0 | N19: 279.8 | O19: 100173 | P19: 223.84 | Q19: 55.96 | R19: TIER_PRICING_VARIANCE
A20: 48 | B20: Martin, Rose and Obrien | C20: Enterprise | D20: 5048 | E20: 46023 | F20: 124 | G20: 4095 | H20: 4095 | I20: 100 | J20: 99.5 | K20: 0 | L20: 256.84 | M20: 0 | N20: 256.84 | Q20: 256.84 | R20: UNBILLED_USAGE
A21: 52 | B21: Walker LLC | C21: Starter | D21: 5052 | E21: 46023 | F21: 63 | G21: 2056 | H21: 2056 | I21: 95.238 | J21: 98 | K21: 0.25 | L21: 276.33 | M21: 69.08 | N21: 207.25 | O21: 100198 | P21: 276.33 | Q21: -69.08 | R21: MISSED_SLA_CREDIT
A22: 58 | B22: Johnston, Sanchez and Kennedy | C22: Growth | D22: 5058 | E22: 46023 | F22: 85 | G22: 2836 | H22: 3000 | I22: 100 | J22: 99 | K22: 0 | L22: 338.04 | M22: 0 | N22: 338.04 | Q22: 338.04 | R22: UNBILLED_USAGE
A23: 60 | B23: Gomez-Jenkins | C23: Starter | D23: 5060 | E23: 46023 | F23: 27 | G23: 836 | H23: 836 | I23: 100 | J23: 98 | K23: 0 | L23: 146.72 | M23: 0 | N23: 146.72 | Q23: 146.72 | R23: UNBILLED_USAGE
A24: 1 | B24: Rodriguez, Figueroa and Sanchez | C24: Starter | D24: 5001 | E24: 46054 | F24: 47 | G24: 1571 | H24: 1600 | I24: 100 | J24: 98 | K24: 0 | L24: 268.96 | M24: 0 | N24: 268.96 | O24: 100204 | P24: 242.06 | Q24: 26.9 | R24: TIER_PRICING_VARIANCE
A25: 9 | B25: Garcia-James | C25: Growth | D25: 5009 | E25: 46054 | F25: 44 | G25: 1322 | H25: 1500 | I25: 97.727 | J25: 99 | K25: 0.25 | L25: 152.01 | M25: 38 | N25: 114.01 | O25: 100212 | P25: 152.01 | Q25: -38 | R25: MISSED_SLA_CREDIT
A26: 22 | B26: Watts, Robinson and Nguyen | C26: Growth | D26: 5022 | E26: 46054 | F26: 89 | G26: 2897 | H26: 2897 | I26: 100 | J26: 99 | K26: 0 | L26: 292.54 | M26: 0 | N26: 292.54 | Q26: 292.54 | R26: UNBILLED_USAGE
A27: 38 | B27: Baker, Mason and White | C27: Growth | D27: 5038 | E27: 46054 | F27: 69 | G27: 2255 | H27: 2255 | I27: 97.101 | J27: 99 | K27: 0.25 | L27: 196.05 | M27: 49.01 | N27: 147.04 | O27: 100239 | P27: 196.05 | Q27: -49.01 | R27: MISSED_SLA_CREDIT
A28: 59 | B28: Lee-Davis | C28: Enterprise | D28: 5059 | E28: 46054 | F28: 176 | G28: 5802 | H28: 5802 | I28: 100 | J28: 99.5 | K28: 0 | L28: 291.03 | M28: 0 | N28: 291.03 | O28: 100258 | P28: 327.41 | Q28: -36.38 | R28: TIER_PRICING_VARIANCE
A29: 5 | B29: Guzman, Hoffman and Baldwin | C29: Enterprise | D29: 5005 | E29: 46082 | F29: 183 | G29: 6397 | H29: 6397 | I29: 100 | J29: 99.5 | K29: 0 | L29: 379.21 | M29: 0 | N29: 379.21 | O29: 100264 | P29: 474.02 | Q29: -94.81 | R29: TIER_PRICING_VARIANCE
A30: 7 | B30: Blake and Sons | C30: Starter | D30: 5007 | E30: 46082 | F30: 50 | G30: 1714 | H30: 1714 | I30: 100 | J30: 98 | K30: 0 | L30: 281.27 | M30: 0 | N30: 281.27 | O30: 100266 | P30: 253.14 | Q30: 28.13 | R30: TIER_PRICING_VARIANCE
A31: 32 | B31: Carlson-Cruz | C31: Enterprise | D31: 5032 | E31: 46082 | F31: 101 | G31: 3536 | H31: 3536 | I31: 100 | J31: 99.5 | K31: 0 | L31: 250.91 | M31: 0 | N31: 250.91 | O31: 100291 | P31: 313.64 | Q31: -62.73 | R31: TIER_PRICING_VARIANCE
A32: 46 | B32: Spence PLC | C32: Growth | D32: 5046 | E32: 46082 | F32: 68 | G32: 2183 | H32: 2183 | I32: 100 | J32: 99 | K32: 0 | L32: 214.55 | M32: 0 | N32: 214.55 | Q32: 214.55 | R32: UNBILLED_USAGE
A33: 2 | B33: Doyle Ltd | C33: Starter | D33: 5002 | E33: 46113 | F33: 39 | G33: 1230 | H33: 1230 | I33: 100 | J33: 98 | K33: 0 | L33: 210.45 | M33: 0 | N33: 210.45 | O33: 100320 | P33: 168.36 | Q33: 42.09 | R33: TIER_PRICING_VARIANCE
A34: 10 | B34: Abbott-Munoz | C34: Starter | D34: 5010 | E34: 46113 | F34: 34 | G34: 1210 | H34: 1210 | I34: 100 | J34: 98 | K34: 0 | L34: 183.68 | M34: 0 | N34: 183.68 | O34: 100328 | P34: 146.94 | Q34: 36.74 | R34: TIER_PRICING_VARIANCE
A35: 22 | B35: Watts, Robinson and Nguyen | C35: Growth | D35: 5022 | E35: 46113 | F35: 99 | G35: 2988 | H35: 2988 | I35: 100 | J35: 99 | K35: 0 | L35: 301.73 | M35: 0 | N35: 301.73 | Q35: 301.73 | R35: UNBILLED_USAGE
A36: 52 | B36: Walker LLC | C36: Starter | D36: 5052 | E36: 46113 | F36: 52 | G36: 1665 | H36: 1665 | I36: 100 | J36: 98 | K36: 0 | L36: 223.78 | M36: 0 | N36: 223.78 | Q36: 223.78 | R36: UNBILLED_USAGE
A37: 58 | B37: Johnston, Sanchez and Kennedy | C37: Growth | D37: 5058 | E37: 46113 | F37: 100 | G37: 3388 | H37: 3388 | I37: 98 | J37: 99 | K37: 0.25 | L37: 381.76 | M37: 95.44 | N37: 286.32 | O37: 100374 | P37: 381.76 | Q37: -95.44 | R37: MISSED_SLA_CREDIT
A38: 3 | B38: Mcclain, Miller and Henderson | C38: Growth | D38: 5003 | E38: 46143 | F38: 37 | G38: 1335 | H38: 1400 | I38: 100 | J38: 99 | K38: 0 | L38: 151.58 | M38: 0 | N38: 151.58 | O38: 100379 | P38: 134.74 | Q38: 16.84 | R38: TIER_PRICING_VARIANCE
A39: 11 | B39: Blair PLC | C39: Enterprise | D39: 5011 | E39: 46143 | F39: 103 | G39: 3344 | H39: 3344 | I39: 100 | J39: 99.5 | K39: 0 | L39: 184.05 | M39: 0 | N39: 184.05 | Q39: 184.05 | R39: UNBILLED_USAGE
A40: 19 | B40: Adams, Zuniga and Wong | C40: Growth | D40: 5019 | E40: 46143 | F40: 90 | G40: 2934 | H40: 2934 | I40: 100 | J40: 99 | K40: 0 | L40: 298.92 | M40: 0 | N40: 298.92 | O40: 100394 | P40: 332.13 | Q40: -33.21 | R40: TIER_PRICING_VARIANCE
...
